Workbook

Sheet april 
C2: Money | F2: Savings Account | I2: Name | J2: Value | K2: Paid? | L2: Who
C3: Paid | D3: 3930.71 | F3: Savings Account | G3: 420 | I3: Mortgage | J3: -797 | K3: no
C4: Taken Already | D4: =SUMIF(K3:K29,"Yes*",J3:J29) -> 0 | I4: Car | J4: -244.8 | K4: no | L4: f
C5: Balance | D5: 3930 | F5: train | I5: LifeInsurance/aviva | J5: -25.56 | K5: no
C6: To Be Taken | D6: =SUMIF(K3:K33,"No",J3:J33) -> -3737.73 | F6: francesca christmas | I6: HouseInsurance - Tesco | J6: -24.82 | K6: no
C7: Total | D7: =D6+D5 -> 192.27 | F7: rumpus vet fund | G7: 151 | I7: TvLicence | J7: -13.2 | K7: no
C8: Francesca | D8: =SUMIF(L3:L33,"f",J3:J33) -> -1722.3 | F8: EDF BUFFER | G8: 35 | I8: Gas/Electric | J8: -229 | K8: no
I9: pet insur | J9: -35 | K9: no
D10: 4042 | F10: francesca cashback | I10: spotoify | J10: -16.99 | K10: no
D11: =D5-D10 -> -112 | F11: Saving Total | G11: =SUM(G3:G10) -> 606 | I11: loan | J11: -395 | K11: no
I12: netflix | J12: -13.99 | K12: no
F13: Botox | G13: 290 | I13: plus net | J13: -28.22 | K13: no
I14: council tax | J14: -209 | K14: no
C15: Mortgage | I15: water | J15: -16 | K15: no
C16: Main | D16: 167660.11 | I16: GARDEN | J16: -6.25 | K16: no
C17: Extra | D17: 87559.93 | I17: water | J17: -35 | K17: no
C18: Total Due | D18: =SUM(D16:D17) -> 255220.04 | I18: hp | J18: -3 | K18: no
C19: H2B paybak | D19: =D20*0.2 -> 84000 | F19: loan is 2600.00 | G19: 1082 | I19: HSBC CC | J19: -600 | K19: no | L19: f
C20: Sold Price | D20: 420000 | F20: Paid 1 | G20: 160 | I20: swimming | K20: no
C21: Equity | D21: =SUM(D18:D19)-D20 -> -80779.96 | F21: Paid 1 | I21: Tesco Mobile | J21: -12.5 | K21: no | L21: f
F22: Paid 1 | I22: tesco card | K22: no | L22: f
F23: Paid 1 | I23: food petrol | J23: -750 | K23: no | L23: f
G24: =SUM(G20:G23)-G19 -> -922 | I24: window cleaner | J24: -10 | K24: no
C25: 4170 with oncall | I25: greenbelt | J25: -7.4 | K25: no
C26: 3930.00 without | D26: 60 | I26: next | K26: no | L26: f
I27: car insurance lv | J27: -35 | K27: no
I28: child benefit shit | J28: -85 | K28: no | L28: f
I29: train | J29: -115 | K29: no
I30: gym | J30: -30 | K30: no | L30: f
I31: matts credit | K31: no
I32: edf buffer | K32: no
D33: =SUM(D26:D32) -> 60 | I33: savings | K33: no
K34: no
K35: no

Sheet feb26
A1: Money | E1: Savings Account | H1: Name | I1: Value | J1: Paid? | K1: Who
A2: Paid | B2: 5225 | E2: Rainy Day 🌧️ | F2: 50 | H2: Mortgage | I2: -1117 | J2: no
A3: Taken Already | B3: =SUMIF(J2:J47,"Yes*",I2:I47) -> 0 | E3: botox | H3: stocks and shares isa | I3: -143 | J3: no | K3: s
A4: Balance | B4: 5225 | E4: Dental 🪥 | F4: 120 | H4: LifeInsurance/aviva | I4: -39 | J4: no
A5: To Be Taken | B5: =SUMIF(J2:J47,"No",I2:I47) -> -5207.67 | E5: Vet Fund 😺 | F5: 620 | H5: HouseInsurance - Tesco | I5: -39 | J5: no
A6: Total | B6: =B5+B4 -> 17.33 | E6: christmas | F6: 974 | H6: TvLicence | I6: -15 | J6: no
A7: Francesca pt 1 | B7: =SUMIF(K2:K47,"f1",I2:I47) -> -2017.99 | E7: willow bday | F7: 200 | H7: Gas/Electric | I7: -185 | J7: no
A8: Francesca pt 2 | B8: =SUMIF(K2:K47,"f2",I2:I47) -> -48 | E8: 5 week | F8: 100 | H8: pet insur | I8: -40 | J8: no | K8: s
A9: Matt | B9: =SUMIF(K2:K47,"",I2:I47) -> -2958.68 | H9: spotoify | I9: -22 | J9: no
A10: Savings | B10: =SUMIF(K2:K47,"s",I2:I47) -> -183 | E10: TAX | H10: rumpus food | I10: -55 | J10: no
A11: Mortgage | E11: Saving Total | F11: =SUM(F2:F10) -> 2064 | H11: rumpus arun vet | I11: -7.99 | J11: no | K11: f1
A12: Main | B12: 151455.79 | C12: 27yrs 8 Months | H12: amazon | I12: -8.99 | J12: no
A13: Extra | B13: 80139.8 | C13: 0.0482 | E13: francesca Isa | F13: 22500 | H13: council tax | I13: -239 | J13: no
A14: Total Due | B14: =SUM(B12:B13) -> 231595.59 | E14: savings | F14: 1000 | H14: water | I14: -13 | J14: no
A15: H2B paybak | B15: =B16*0.2 -> 92000 | E15: botox | H15: window clean | I15: -10 | J15: no
A16: Sold Price | B16: 460000 | E16: me | H16: water | I16: -58 | J16: no
A17: Equity | B17: =B16-SUM(B14:B15) -> 136404.41 | E17: matt bday | H17: hp | I17: -1.5 | J17: no
E18: matt gift | H18: DISHWASHER | I18: -5 | J18: no
E19: mattchristmas | H19: fran money for card | I19: -800 | J19: no | K19: f1
E20: christmas | H20: tesco mobiles | I20: -28 | J20: no | K20: f2
E21: FRANNYS MONEY | F21: =SUM(F15:F20) -> 0 | H21: green belt | I21: -14.99 | J21: no
E22: JL092865B | H22: food petrol | I22: -930 | J22: no | K22: f1
H23: willow bday | I23: -150 | J23: no
H24: botox | I24: -75 | J24: no | K24: f1
H25: dental | I25: -20 | J25: no
H26: car insurance lv | I26: -27.7 | J26: no
H27: child benefit shit | I27: -90 | J27: no | K27: f1
H28: zoom | I28: -18 | J28: no
H29: 5 week month | I29: -133 | J29: no
A30: NW | H30: boiler | I30: -14.5 | J30: no
A31: 1104841580 | H31: service | I31: -35 | J31: no | K31: f1
H32: matt | I32: -80 | J32: no
H33: pocket money | I33: -25 | J33: no
H34: help to by | I34: -130 | J34: no
H35: lunch | I35: -20 | J35: no | K35: f2
H36: nails | I36: -80 | J36: no | K36: f1
H37: christmas | I37: -50 | J37: no
H38: green waste | I38: -8 | J38: no
H39: emergancy fund | I39: -300 | J39: no
H40: gym | I40: -30 | J40: no
...

Sheet jan26
A1: Money | E1: Savings Account | H1: Name | I1: Value | J1: Paid? | K1: Who
A2: Paid | B2: 5225 | E2: Rainy Day 🌧️ | F2: 50 | H2: Mortgage | I2: -1117 | J2: no
A3: Taken Already | B3: =SUMIF(J2:J47,"Yes*",I2:I47) -> 0 | E3: botox | H3: stocks and shares isa | I3: -143 | J3: no | K3: s
A4: Balance | B4: 5225 | E4: Dental 🪥 | F4: 120 | H4: LifeInsurance/aviva | I4: -39 | J4: no
A5: To Be Taken | B5: =SUMIF(J2:J47,"No",I2:I47) -> -5219.67 | E5: Vet Fund 😺 | F5: 620 | H5: HouseInsurance - Tesco | I5: -39 | J5: no
A6: Total | B6: =B5+B4 -> 5.33 | E6: christmas | F6: 974 | H6: TvLicence | I6: -15 | J6: no
A7: Francesca pt 1 | B7: =SUMIF(K2:K47,"f1",I2:I47) -> -2272.99 | E7: willow bday | F7: 200 | H7: Gas/Electric | I7: -185 | J7: no
A8: Francesca pt 2 | B8: =SUMIF(K2:K47,"f2",I2:I47) -> -48 | E8: 5 week | F8: 100 | H8: pet insur | I8: -40 | J8: no | K8: s
A9: Matt | B9: =SUMIF(K2:K47,"",I2:I47) -> -2715.68 | H9: spotoify | I9: -22 | J9: no
A10: Savings | B10: =SUMIF(K2:K47,"s",I2:I47) -> -183 | E10: TAX | H10: rumpus food | I10: -55 | J10: no
A11: Mortgage | E11: Saving Total | F11: =SUM(F2:F10) -> 2064 | H11: rumpus arun vet | I11: -7.99 | J11: no | K11: f1
A12: Main | B12: 151455.79 | C12: 27yrs 8 Months | H12: amazon | I12: -8.99 | J12: no
A13: Extra | B13: 80139.8 | C13: 0.0482 | E13: francesca Isa | F13: 22500 | H13: council tax | I13: -239 | J13: no
A14: Total Due | B14: =SUM(B12:B13) -> 231595.59 | E14: savings | F14: 1000 | H14: water | I14: -13 | J14: no
A15: H2B paybak | B15: =B16*0.2 -> 92000 | E15: botox | H15: window clean | I15: -10 | J15: no
A16: Sold Price | B16: 460000 | E16: me | H16: water | I16: -58 | J16: no
A17: Equity | B17: =B16-SUM(B14:B15) -> 136404.41 | E17: matt bday | H17: hp | I17: -1.5 | J17: no
E18: matt gift | H18: DISHWASHER | I18: -5 | J18: no
E19: mattchristmas | H19: fran money for card | I19: -1000 | J19: no | K19: f1
E20: christmas | H20: tesco mobiles | I20: -28 | J20: no | K20: f2
E21: FRANNYS MONEY | F21: =SUM(F15:F20) -> 0 | H21: green belt | I21: -14.99 | J21: no
E22: JL092865B | H22: food petrol | I22: -930 | J22: no | K22: f1
H23: willow bday | I23: -150 | J23: no
H24: botox | I24: -130 | J24: no | K24: f1
H25: dental | I25: -20 | J25: no
H26: car insurance lv | I26: -27.7 | J26: no
H27: child benefit shit | I27: -90 | J27: no | K27: f1
H28: zoom | I28: -18 | J28: no
H29: gym | I29: -30 | J29: no
A30: NW | H30: boiler | I30: -14.5 | J30: no
A31: 1104841580 | H31: service | I31: -35 | J31: no | K31: f1
H32: matt | I32: -80 | J32: no
H33: pocket money | I33: -25 | J33: no
H34: help to by | I34: -130 | J34: no
H35: lunch | I35: -20 | J35: no | K35: f2
H36: nails | I36: -80 | J36: no | K36: f1
H37: christmas | I37: -50 | J37: no
H38: green waste | I38: -8 | J38: no
H39: health insurance | I39: -200 | J39: no
H40: bercleys | I40: -140 | J40: no
...

Sheet dec25
A1: Money | E1: Savings Account | H1: Name | I1: Value | J1: Paid? | K1: Who
A2: Paid | B2: 5225 | H2: Mortgage | I2: -1268.67 | J2: no
A3: Taken Already | B3: =SUMIF(J2:J47,"Yes*",I2:I47) -> 0 | H3: isa | J3: no | K3: s
A4: Balance | B4: 5223 | E4: Dental 🪥 | F4: 5 | H4: LifeInsurance/aviva | I4: -39 | J4: no
A5: To Be Taken | B5: =SUMIF(J2:J47,"No",I2:I47) -> -5218.34 | E5: Vet Fund 😺 | F5: 525 | H5: HouseInsurance - Tesco | I5: -39 | J5: no
A6: Total | B6: =B5+B4 -> 4.66 | E6: christmas | F6: 509 | H6: TvLicence | I6: -15 | J6: no
A7: Francesca pt 1 | B7: =SUMIF(K2:K47,"f1",I2:I47) -> -2387.99 | H7: Gas/Electric | I7: -185 | J7: no
A8: Francesca pt 2 | B8: =SUMIF(K2:K47,"f2",I2:I47) -> -148 | H8: pet insur | I8: -40 | J8: no | K8: s
A9: Matt | B9: =SUMIF(K2:K47,"",I2:I47) -> -2642.35 | H9: spotoify | I9: -22 | J9: no
A10: Savings | B10: =SUMIF(K2:K47,"s",I2:I47) -> -40 | E10: TAX | H10: rumpus food | I10: -55 | J10: no
A11: Mortgage | E11: Saving Total | F11: =SUM(F2:F10) -> 1039 | H11: rumpus arun vet | I11: -7.99 | J11: no | K11: f1
A12: Main | B12: 151455.79 | C12: 27yrs 8 Months | H12: amazon | I12: -8.99 | J12: no
A13: Extra | B13: 80139.8 | C13: 0.0482 | E13: francesca Isa | F13: 22500 | H13: council tax | I13: -239 | J13: no
A14: Total Due | B14: =SUM(B12:B13) -> 231595.59 | E14: savings | F14: 1000 | H14: water | I14: -13 | J14: no
A15: H2B paybak | B15: =B16*0.2 -> 92000 | E15: botox | F15: 127 | H15: window clean | I15: -10 | J15: no
A16: Sold Price | B16: 460000 | E16: me | H16: water | I16: -58 | J16: no
A17: Equity | B17: =B16-SUM(B14:B15) -> 136404.41 | E17: matt bday | H17: hp | I17: -1.5 | J17: no
E18: matt gift | H18: DISHWASHER | I18: -5 | J18: no
E19: mattchristmas | H19: fran money for card | I19: -800 | J19: no | K19: f1
E20: christmas | H20: tesco mobiles | I20: -28 | J20: no | K20: f2
E21: FRANNYS MONEY | F21: =SUM(F15:F20) -> 127 | H21: green belt | I21: -14.99 | J21: no
E22: JL092865B | H22: food petrol | I22: -1170 | J22: no | K22: f1
H23: DINNER | I23: -70 | J23: no
H24: hlf term | I24: -200 | J24: no | K24: f1
H25: dental | I25: -20 | J25: no
H26: car insurance lv | I26: -27.7 | J26: no
H27: child benefit shit | I27: -90 | J27: no | K27: f1
H28: zoom | I28: -18 | J28: no
H29: new years | I29: -100 | J29: no | K29: f2
A30: NW | H30: boiler | I30: -14.5 | J30: no
A31: 1104841580 | H31: service | I31: -35 | J31: no | K31: f1
H32: matt | I32: -75 | J32: no
H33: pocket money | I33: -25 | J33: no
H34: help to by | I34: -130 | J34: no
H35: lunch | I35: -20 | J35: no | K35: f2
H36: nails | I36: -85 | J36: no | K36: f1
H37: christmas | I37: -200 | J37: no
H38: green waste | I38: -8 | J38: no
H39: mum and dad bday | I39: -50 | J39: no
H40: gym | I40: -30 | J40: no
...

Sheet nov25
A1: Money | E1: Savings Account | H1: Name | I1: Value | J1: Paid? | K1: Who
A2: Paid | B2: 5237.04 | E2: Rainy Day 🌧️ | F2: 1 | H2: Mortgage | I2: -1268.67 | J2: yes
A3: Taken Already | B3: =SUMIF(J2:J47,"Yes*",I2:I47) -> -5240.45 | H3: westfields | I3: -70 | J3: yes | K3: s
A4: Balance | B4: 35.86 | E4: Dental 🪥 | F4: 5 | H4: LifeInsurance/aviva | I4: -39 | J4: yes
A5: To Be Taken | B5: =SUMIF(J2:J47,"No",I2:I47) -> -32.5 | E5: Vet Fund 😺 | F5: 525 | H5: HouseInsurance - Tesco | I5: -35 | J5: yes
A6: Total | B6: =B5+B4 -> 3.36 | E6: christmas | F6: 240 | H6: TvLicence | I6: -15 | J6: yes
A7: Francesca pt 1 | B7: =SUMIF(K2:K47,"f1",I2:I47) -> -2255.99 | H7: Gas/Electric | I7: -185 | J7: yes
A8: Francesca pt 2 | B8: =SUMIF(K2:K47,"f2",I2:I47) -> 0 | H8: pet insur | I8: -40 | J8: yes | K8: s
A9: Matt | B9: =SUMIF(K2:K47,"",I2:I47) -> -2871.96 | H9: spotoify | I9: -22 | J9: yes
A10: Savings | B10: =SUMIF(K2:K47,"s",I2:I47) -> -110 | E10: TAX | H10: rumpus food | I10: -55 | J10: yes
A11: Mortgage | E11: Saving Total | F11: =SUM(F2:F10) -> 771 | H11: rumpus arun vet | I11: -7.99 | J11: yes | K11: f1
A12: Main | B12: 151455.79 | C12: 27yrs 8 Months | H12: amazon | I12: -8.99 | J12: yes
A13: Extra | B13: 80139.8 | C13: 0.0482 | E13: francesca Isa | F13: 22057 | H13: council tax | I13: -239 | J13: yes
A14: Total Due | B14: =SUM(B12:B13) -> 231595.59 | E14: savings | F14: 1011 | H14: water | I14: -26 | J14: no
A15: H2B paybak | B15: =B16*0.2 -> 92000 | E15: s and shares | F15: 68.26 | H15: window clean | J15: no
A16: Sold Price | B16: 460000 | E16: me | H16: water | I16: -58 | J16: yes
A17: Equity | B17: =B16-SUM(B14:B15) -> 136404.41 | E17: matt bday | H17: hp | I17: -1.5 | J17: no
E18: matt gift | H18: DISHWASHER | I18: -5 | J18: no
E19: mattchristmas | H19: fran money for card | I19: -800 | J19: yes | K19: f1
B20: 579 | E20: christmas | H20: tesco mobiles | I20: -28 | J20: yes | K20: f1
B21: 245 teeth | E21: FRANNYS MONEY | F21: =SUM(F15:F20) -> 68.26 | H21: green belt | I21: -7.6 | J21: yes
B22: 334 | E22: JL092865B | H22: food petrol | I22: -930 | J22: yes | K22: f1
H23: fran credit card | I23: -210 | J23: yes | K23: f1
H24: credit card | I24: -131 | J24: yes
H25: dental | I25: -20 | J25: yes
H26: car insurance lv | I26: -27.7 | J26: yes
H27: child benefit shit | I27: -40 | J27: yes | K27: f1
H28: zoom | I28: -18 | J28: yes
H29: christmas | I29: -470 | J29: yes
A30: NW | H30: boiler | I30: -14.5 | J30: yes
A31: 1104841580 | H31: service | I31: -35 | J31: yes | K31: f1
H32: matt | I32: -60 | J32: yes
H33: pocket money | I33: -25 | J33: yes | K33: w
H34: help to by | I34: -130 | J34: yes
H35: lunch | I35: -20 | J35: yes | K35: f1
H36: nails | I36: -80 | J36: yes | K36: f1
H37: trip for h o p | I37: -10 | J37: yes | K37: w
H38: green waste | I38: -8 | J38: yes
H39: next | I39: -75 | J39: yes | K39: f1
H40: gym | I40: -30 | J40: yes | K40: f1
...

Sheet oct25
A1: Money | E1: Savings Account | H1: Name | I1: Value | J1: Paid? | K1: Who
A2: Paid | B2: 5223.85 | E2: Rainy Day 🌧️ | H2: Mortgage | I2: -1268.67 | J2: yes
A3: Taken Already | B3: =SUMIF(J2:J47,"Yes*",I2:I47) -> -5201.35 | H3: insurance | I3: -200 | J3: yes | K3: s
A4: Balance | B4: 84.44 | E4: Dental 🪥 | F4: 60 | H4: LifeInsurance/aviva | I4: -39 | J4: yes
A5: To Be Taken | B5: =SUMIF(J2:J47,"No",I2:I47) -> -80 | E5: Vet Fund 😺 | F5: 580 | H5: HouseInsurance - Tesco | I5: -39 | J5: yes
A6: Total | B6: =B5+B4 -> 4.44 | E6: christmas | F6: 185 | H6: TvLicence | I6: -15 | J6: yes
A7: Francesca pt 1 | B7: =SUMIF(K2:K47,"f1",I2:I47) -> -2031 | H7: Gas/Electric | I7: -185 | J7: yes
A8: Francesca pt 2 | B8: =SUMIF(K2:K47,"f2",I2:I47) -> -480 | H8: pet insur | I8: -20 | J8: yes | K8: s
A9: Matt | B9: =SUMIF(K2:K47,"",I2:I47) -> -2550.35 | H9: spotoify | I9: -20 | J9: yes
A10: Savings | B10: =SUMIF(K2:K47,"s",I2:I47) -> -220 | E10: TAX | H10: rumpus food | I10: -55 | J10: yes
A11: Mortgage | E11: Saving Total | F11: =SUM(F2:F10) -> 825 | H11: rumpus arun vet | I11: -8 | J11: yes | K11: f1
A12: Main | B12: 150603.12 | C12: 27yrs 8 Months | E12: emergancy fund | F12: 1011 | H12: amazon | I12: -8.99 | J12: yes
A13: Extra | B13: 79688.61 | C13: 0.0482 | E13: francesca Isa | F13: 22586.69 | H13: council tax | I13: -239 | J13: yes
A14: Total Due | B14: =SUM(B12:B13) -> 230291.73 | E14: s and shares isa | F14: 69.28 | H14: water | I14: -13 | J14: yes
A15: H2B paybak | B15: =B16*0.2 -> 92000 | H15: window clean | I15: -10 | J15: yes
A16: Sold Price | B16: 460000 | E16: me | H16: water | I16: -58 | J16: yes
A17: Equity | B17: =B16-SUM(B14:B15) -> 137708.27 | E17: matt bday | H17: hp | I17: -1.5 | J17: yes
H18: DISHWASHER | I18: -5 | J18: no
H19: fran money for card | I19: -800 | J19: yes | K19: f1
E20: christmas | H20: tesco mobiles | I20: -28 | J20: yes | K20: f1
E21: total | F21: =SUM(F11:F15) -> 24491.97 | H21: green belt | I21: -14.99 | J21: yes
E22: JL092865B | H22: food petrol | I22: -920 | J22: yes | K22: f1
H23: plummer | I23: -75 | J23: no
H24: credit card | J24: no | K24: f1
H25: dental | I25: -20 | J25: yes
H26: car insurance lv | I26: -27.7 | J26: yes
H27: child benefit shit | I27: -70 | J27: yes | K27: f1
H28: zoom | I28: -18 | J28: yes
H29: christmas | I29: -480 | J29: yes | K29: f2
A30: NW | H30: boiler | I30: -14.5 | J30: yes
A31: 1104841580 | H31: service | I31: -35 | J31: yes | K31: f1
H32: matt | I32: -80 | J32: yes
H33: pocket money | I33: -25 | J33: yes
H34: help to by | I34: -130 | J34: yes
H35: lunch | I35: -20 | J35: yes | K35: f1
H36: nails | I36: -20 | J36: yes | K36: f1
H37: half termm | I37: -100 | J37: yes | K37: f1
H38: green waste | I38: -8 | J38: yes
H39: london | I39: -100 | J39: yes
H40: gym | I40: -30 | J40: yes | K40: f1
...

Sheet sept25
A1: Money | E1: Savings Account | H1: Name | I1: Value | J1: Paid? | K1: Who
A2: Paid | B2: 5251.07 | E2: Rainy Day 🌧️ | F2: 50 | H2: Mortgage | I2: -1268.67 | J2: yes
A3: Taken Already | B3: =SUMIF(J2:J47,"Yes*",I2:I47) -> -5502.34 | J3: no | K3: s
A4: Balance | B4: 7.85 | E4: Dental 🪥 | F4: 110 | H4: LifeInsurance/aviva | I4: -39 | J4: yes
A5: To Be Taken | B5: =SUMIF(J2:J47,"No",I2:I47) -> -5 | E5: Vet Fund 😺 | F5: 520 | H5: HouseInsurance - Tesco | I5: -39 | J5: yes
A6: Total | B6: =B5+B4 -> 2.85 | E6: christmas | F6: 488 | H6: TvLicence | I6: -15 | J6: yes
A7: Francesca pt 1 | B7: =SUMIF(K2:K47,"f1",I2:I47) -> -2550.99 | H7: Gas/Electric | I7: -185 | J7: yes
A8: Francesca pt 2 | B8: =SUMIF(K2:K47,"f2",I2:I47) -> -220 | E8: Savings | H8: pet insur | J8: no | K8: s
A9: Matt | B9: =SUMIF(K2:K47,"",I2:I47) -> -2736.35 | H9: spotoify | I9: -20 | J9: yes
A10: Savings | B10: =SUMIF(K2:K47,"s",I2:I47) -> 0 | E10: TAX | H10: rumpus food | I10: -55 | J10: yes
A11: Mortgage | E11: Saving Total | F11: =SUM(F2:F10) -> 1168 | H11: rumpus arun vet | I11: -7.99 | J11: yes | K11: f1
A12: Main | B12: 151455.79 | C12: 27yrs 8 Months | H12: amazon | I12: -8.99 | J12: yes
A13: Extra | B13: 80139.8 | C13: 0.0482 | E13: francesca Isa | F13: 22590.67 | H13: council tax | I13: -239 | J13: yes
A14: Total Due | B14: =SUM(B12:B13) -> 231595.59 | E14: savings | F14: 1000 | H14: water | I14: -13 | J14: yes
A15: H2B paybak | B15: =B16*0.2 -> 97800 | E15: botox | F15: 126.97 | H15: window clean | J15: no
A16: Sold Price | B16: 489000 | E16: me | H16: water | I16: -58 | J16: yes
A17: Equity | B17: =B16-SUM(B14:B15) -> 159604.41 | E17: matt bday | H17: hp | I17: -1.5 | J17: yes
E18: matt meals | F18: 350 | H18: DISHWASHER | I18: -5 | J18: no
E19: mattchristmas | F19: 110 | H19: fran money for card | I19: -1000 | J19: yes | K19: f1
H20: tesco mobiles | I20: -28 | J20: yes | K20: f1
E21: FRANNYS MONEY | F21: =SUM(F15:F20) -> 586.97 | H21: green belt | I21: -14.99 | J21: yes
E22: JL092865B | H22: food petrol | I22: -1170 | J22: yes | K22: f1
H23: fran | I23: -50 | J23: yes
H24: credit card | I24: -200 | J24: yes | K24: f1
H25: dental | I25: -20 | J25: yes
H26: car insurance lv | I26: -27.7 | J26: yes
H27: child benefit shit | I27: -80 | J27: yes | K27: f1
H28: zoom | I28: -18 | J28: yes
H29: christmas | I29: -210 | J29: yes | K29: f2
A30: NW | H30: boiler | I30: -14.5 | J30: yes
A31: 1104841580 | H31: service | I31: -35 | J31: yes | K31: f1
H32: matt | I32: -50 | J32: yes
H33: pocket money | I33: -25 | J33: yes
H34: help to by | I34: -130 | J34: yes
H35: lunch | I35: -10 | J35: yes | K35: f2
H36: nails | I36: -60 | J36: yes
H37: matt credit | I37: -35 | J37: yes
H38: green waste | I38: -8 | J38: yes
H39: gym | I39: -30 | J39: yes | K39: f1
H40: matt | I40: -321 | J40: yes
...

Sheet aug25
A1: Money | E1: Savings Account | H1: Name | I1: Value | J1: Paid? | K1: Who
A2: Paid | B2: 5245.45 | E2: Rainy Day 🌧️ | F2: 60 | H2: Mortgage | I2: -1268.67 | J2: yes
A3: Taken Already | B3: =SUMIF(J2:J47,"Yes*",I2:I47) -> -5212.11 | H3: isa | J3: no | K3: s
A4: Balance | B4: 133.01 | E4: Dental 🪥 | F4: 110 | H4: LifeInsurance/aviva | I4: -39 | J4: yes
A5: To Be Taken | B5: =SUMIF(J2:J47,"No",I2:I47) -> 0 | E5: Vet Fund 😺 | F5: 600 | H5: HouseInsurance - Tesco | I5: -39 | J5: yes
A6: Total | B6: =B5+B4 -> 133.01 | H6: TvLicence | I6: -15 | J6: yes
A7: Francesca pt 1 | B7: =SUMIF(K2:K47,"f1",I2:I47) -> -2137.99 | H7: Gas/Electric | I7: -185 | J7: yes
A8: Francesca pt 2 | B8: =SUMIF(K2:K47,"f2",I2:I47) -> -150 | E8: Savings | H8: pet insur | I8: -40 | J8: yes | K8: s
A9: Matt | B9: =SUMIF(K2:K47,"",I2:I47) -> -2884.12 | H9: spotoify | I9: -20 | J9: yes
A10: Savings | B10: =SUMIF(K2:K47,"s",I2:I47) -> -40 | E10: TAX | H10: rumpus food | I10: -55 | J10: yes
A11: Mortgage | E11: Saving Total | F11: =SUM(F2:F10) -> 770 | H11: rumpus arun vet | I11: -7.99 | J11: yes | K11: f1
A12: Main | B12: 151011.39 | H12: amazon | I12: -8.99 | J12: yes
A13: Extra | B13: 79904.64 | E13: francesca Isa | F13: 20000 | H13: council tax | I13: -239 | J13: yes
A14: Total Due | B14: =SUM(B12:B13) -> 230916.03 | E14: RICS and H2B | F14: 4000 | H14: water | I14: -13 | J14: yes
A15: H2B paybak | B15: =B16*0.2 -> 92000 | E15: botox | F15: 209.5 | H15: window clean | I15: -10 | J15: yes
A16: Sold Price | B16: 460000 | E16: me | H16: water | I16: -58 | J16: yes
A17: Equity | B17: =B16-SUM(B14:B15) -> 137083.97 | E17: matt trip | F17: 500 | H17: hp | I17: -1.5 | J17: yes
E18: matt gift | F18: 400 | H18: DISHWASHER | I18: -5 | J18: yes
E19: mattchristmas | F19: 200 | H19: fran money for card | I19: -800 | J19: yes | K19: f1
E20: christmas | F20: 351 | H20: tesco mobiles | I20: -28 | J20: yes | K20: f1
E21: FRANNYS MONEY | F21: =SUM(F15:F20) -> 1660.5 | H21: green belt | I21: -14.99 | J21: yes
E22: JL092865B | H22: food petrol | I22: -920 | J22: yes | K22: f1
H23: phone | I23: -11 | J23: yes
H24: next | I24: -47 | J24: yes | K24: f1
H25: dental | J25: no
H26: car insurance lv | I26: -27.7 | J26: yes
E27: NW | H27: child benefit shit | I27: -90 | J27: yes | K27: f1
E28: 1104841580 | H28: zoom | I28: -18 | J28: yes
H29: fran credit | I29: -120 | J29: yes | K29: f1
H30: boiler | I30: -14.5 | J30: yes
H31: service | I31: -35 | J31: yes | K31: f1
H32: matt | I32: -17 | J32: yes
H33: pocket money | I33: -25 | J33: yes
H34: help to by | I34: -130 | J34: yes
H35: christmas | I35: -150 | J35: yes | K35: f2
H36: nails | I36: -60 | J36: yes | K36: f1
H37: applee | I37: -11 | J37: yes
H38: green waste | I38: -8 | J38: yes
H39: summer holidays | I39: -400 | J39: yes
H40: gym | I40: -30 | J40: yes | K40: f1
...

Sheet july25
A1: Money | D1: Savings Account | G1: Name | H1: Value | I1: Paid? | J1: Who
A2: Paid | B2: 5252.27 | D2: Rainy Day 🌧️ | E2: 80 | G2: Mortgage | H2: -1268.67 | I2: yes
A3: Taken Already | B3: =SUMIF(I2:I47,"Yes*",H2:H47) -> -5233.34 | G3: isa | I3: no | J3: s
A4: Balance | B4: 32.22 | D4: Dental 🪥 | E4: 110 | G4: LifeInsurance/aviva | H4: -39 | I4: yes
A5: To Be Taken | B5: =SUMIF(I2:I47,"No",H2:H47) -> 0 | D5: Vet Fund 😺 | E5: 560 | G5: HouseInsurance - Tesco | H5: -39 | I5: yes
A6: Total | B6: =B5+B4 -> 32.22 | G6: TvLicence | H6: -15 | I6: yes
A7: Francesca pt 1 | B7: =SUMIF(J2:J47,"f1",H2:H47) -> -2270.99 | D7: furnitiure | G7: Gas/Electric | H7: -155 | I7: yes
A8: Francesca pt 2 | B8: =SUMIF(J2:J47,"f2",H2:H47) -> -70 | D8: Savings | G8: pet insur | H8: -40 | I8: yes | J8: s
A9: Matt | B9: =SUMIF(J2:J47,"",H2:H47) -> -2852.35 | G9: spotoify | H9: -20 | I9: yes
A10: Savings | B10: =SUMIF(J2:J47,"s",H2:H47) -> -40 | D10: TAX | G10: rumpus food | H10: -55 | I10: yes
D11: Saving Total | E11: =SUM(E2:E10) -> 750 | G11: rumpus arun vet | H11: -7.99 | I11: yes | J11: f1
G12: amazon | H12: -8.99 | I12: yes
A13: Emergency Target | B13: 10000 | D13: francesca Isa | E13: 4025 | G13: council tax | H13: -239 | I13: yes
A14: Emergency Fund | B14: 4000 | G14: water | H14: -13 | I14: yes
A15: Emergency Left | D15: botox | E15: 208 | G15: window clean | H15: -10 | I15: yes
A16: Percentage | B16: =B14/B13 -> 0.4 | D16: me | E16: 200 | G16: water | H16: -57 | I16: yes
D17: matt trip | E17: 500 | G17: hp | H17: -1.5 | I17: yes
A18: Mortgage | D18: matt gift | E18: 400 | G18: DISHWASHER | H18: -5 | I18: yes
A19: Main | B19: 151455.79 | D19: mattchristmas | E19: 200 | G19: fran money for card | H19: -800 | I19: yes | J19: f1
A20: Extra | B20: 80139.8 | D20: christmas | E20: 200 | G20: tesco mobiles | H20: -28 | I20: yes | J20: f1
A21: Total Due | B21: =SUM(B19:B20) -> 231595.59 | D21: FRANNYS MONEY | E21: =SUM(E15:E20) -> 1708 | G21: green belt | H21: -14.99 | I21: yes
A22: H2B paybak | B22: =B23*0.2 -> 92000 | D22: JL092865B | G22: food petrol | H22: -900 | I22: yes | J22: f1
A23: Sold Price | B23: 460000 | G23: phone | H23: -11 | I23: yes
A24: Equity | B24: =B23-SUM(B21:B22) -> 136404.41 | G24: next | H24: -80 | I24: yes
G25: dental | H25: -20 | I25: yes
G26: car insurance lv | H26: -27.7 | I26: yes
G27: child benefit shit | I27: yes | J27: f1
G28: zoom | H28: -18 | I28: yes
I29: no
A30: NW | G30: boiler | H30: -14.5 | I30: yes
A31: 1104841580 | G31: service | H31: -35 | I31: yes | J31: f1
G32: matt | H32: -75 | I32: yes
G33: pocket money | H33: -20 | I33: yes
G34: help to by | H34: -130 | I34: yes
G35: school uniform | H35: -70 | I35: yes | J35: f2
G36: nails | H36: -60 | I36: yes
G37: applee | H37: -11 | I37: yes
G38: green waste | H38: -8 | I38: yes
G39: summer holidays | H39: -500 | I39: yes | J39: f1
G40: matt | H40: -136 | I40: yes
...

Sheet xmas
A1: mum and dad | B1: 150
A2: natalie and tom
A3: willow
A6: anita and andrew | D6: in willows hsbc
A7: matts parents
A8: misc
A9: willows stocking | H9: lokin | I9: 15
A10: fran | H10: david | I10: 4
A11: get from will mummy | H11: aviv | I11: 10
A12: food | B12: 290 | H12: levi | I12: 10
A13: gift 4 daddy willow | H13: charlotte
D14: current | E14: 240 | H14: georgina
D15: nov | H15: realan | I15: 5
A16: total | B16: =SUM(B1:B15) -> 440 | D16: dec | E16: 200 | H16: jackson | I16: 5
E17: =SUM(E14:E16) -> 440 | H17: li
I18: =SUM(I9:I17) -> 49

Sheet june25
A1: Money | D1: Savings Account | G1: Name | H1: Value | I1: Paid? | J1: Who
A2: Paid | B2: 5155.71 | D2: Rainy Day 🌧️ | E2: 80 | G2: Mortgage | H2: -1268.67 | I2: yes
A3: Taken Already | B3: =SUMIF(I2:I47,"Yes*",H2:H47) -> -5436.97 | G3: isa | I3: no | J3: s
A4: Balance | B4: 31.91 | D4: Dental 🪥 | E4: 90 | G4: LifeInsurance/aviva | H4: -39 | I4: yes
A5: To Be Taken | B5: =SUMIF(I2:I47,"No",H2:H47) -> 0 | D5: Vet Fund 😺 | E5: 560 | G5: HouseInsurance - Tesco | H5: -35 | I5: yes
A6: Total | B6: =B5+B4 -> 31.91 | G6: TvLicence | H6: -9.75 | I6: yes
A7: Francesca pt 1 | B7: =SUMIF(J2:J47,"f1",H2:H47) -> -2392.99 | D7: silverstone | G7: Gas/Electric | H7: -155 | I7: yes
A8: Francesca pt 2 | B8: =SUMIF(J2:J47,"f2",H2:H47) -> -48 | D8: festival | G8: pet insur | I8: no | J8: s
A9: Matt | B9: =SUMIF(J2:J47,"",H2:H47) -> -2995.98 | G9: spotoify | H9: -20 | I9: yes
A10: Savings | B10: =SUMIF(J2:J47,"s",H2:H47) -> 0 | D10: TAX | G10: rumpus food | H10: -55 | I10: yes
D11: Saving Total | E11: =SUM(E2:E10) -> 730 | G11: rumpus arun vet | H11: -7.99 | I11: yes | J11: f1
G12: amazon | H12: -8.99 | I12: yes
A13: Emergency Target | B13: 10000 | D13: francesca Isa | E13: 4508.55 | G13: council tax | H13: -239 | I13: yes
A14: Emergency Fund | B14: 4508.55 | D14: FRANNYS MONEY | G14: water | H14: -13 | I14: yes
A15: Emergency Left | G15: window clean | H15: -10 | I15: yes
A16: Percentage | B16: =B14/B13 -> 0.450855 | G16: water | H16: -53.5 | I16: yes
G17: hp | H17: -1.5 | I17: yes
A18: Mortgage | D18: holiday | G18: DISHWASHER | H18: -5 | I18: yes
A19: Main | B19: 151288.74 | G19: fran money for card | H19: -1000 | I19: yes | J19: f1
A20: Extra | B20: 80051.41 | G20: tesco mobiles | H20: -28 | I20: yes | J20: f2
A21: Total Due | B21: =SUM(B19:B20) -> 231340.15 | G21: green belt | H21: -14.99 | I21: yes
A22: H2B paybak | B22: =B23*0.2 -> 92000 | D22: JL092865B | G22: food petrol | H22: -1150 | I22: yes | J22: f1
A23: Sold Price | B23: 460000 | G23: phone | H23: -11 | I23: yes
A24: Equity | B24: =B23-SUM(B21:B22) -> 136659.85 | G24: mattt | H24: -210 | I24: yes
G25: dental | H25: -20 | I25: yes
G26: car insurance lv | H26: -27.7 | I26: yes
G27: child benefit shit | H27: -80 | I27: yes | J27: f1
G28: zoom | H28: -18 | I28: yes
G29: dad bday | H29: -70 | I29: yes
A30: NW | G30: boiler | H30: -14.5 | I30: yes
A31: 1104841580 | G31: service | H31: -35 | I31: yes | J31: f1
G32: matt | H32: -100 | I32: yes
G33: pocket money | H33: -25 | I33: yes
G34: help to by | H34: -130 | I34: yes
G35: lunch | H35: -20 | I35: yes | J35: f2
G36: nails | H36: -120 | I36: yes | J36: f1
G37: applee | H37: -11 | I37: yes
G38: green waste | H38: -8 | I38: yes
G39: silverstone | H39: -50 | I39: yes
G40: festival of speed | H40: -50 | I40: yes
...

Sheet may25
A1: Money | D1: Savings Account | G1: Name | H1: Value | I1: Paid? | J1: Who
A2: Paid | B2: 5155.71 | D2: Rainy Day 🌧️ | E2: 80 | G2: Mortgage | H2: -1268.67 | I2: yes
A3: Taken Already | B3: =SUMIF(I2:I47,"Yes*",H2:H47) -> -5324.94 | G3: isa | H3: -200 | I3: yes | J3: s
A4: Balance | B4: 13.49 | D4: Dental 🪥 | E4: 70 | G4: LifeInsurance/vitality | H4: -39 | I4: yes
A5: To Be Taken | B5: =SUMIF(I2:I47,"No",H2:H47) -> 0 | D5: Vet Fund 😺 | E5: 560 | G5: HouseInsurance - Tesco | H5: -39 | I5: yes
A6: Total | B6: =B5+B4 -> 13.49 | G6: TvLicence | H6: -15 | I6: yes
A7: Francesca pt 1 | B7: =SUMIF(J2:J47,"f1",H2:H47) -> -2236.99 | D7: furnitiure | G7: Gas/Electric | H7: -155 | I7: yes
A8: Francesca pt 2 | B8: =SUMIF(J2:J47,"f2",H2:H47) -> -81 | D8: Savings | G8: pet insur | H8: -40 | I8: yes | J8: s
A9: Matt | B9: =SUMIF(J2:J47,"",H2:H47) -> -2766.95 | G9: spotoify | H9: -20 | I9: yes
A10: Savings | B10: =SUMIF(J2:J47,"s",H2:H47) -> -240 | D10: TAX | G10: rumpus food | H10: -25 | I10: yes
D11: Saving Total | E11: =SUM(E2:E10) -> 710 | G11: rumpus arun vet | H11: -7.99 | I11: yes | J11: f1
G12: amazon | H12: -8.99 | I12: yes
A13: Emergency Target | B13: 10000 | D13: francesca Isa | E13: 4500 | G13: council tax | H13: -239 | I13: yes
A14: Emergency Fund | B14: 4324 | D14: FRANNYS MONEY | G14: water | H14: -13 | I14: yes
A15: Emergency Left | G15: window clean | H15: -10 | I15: yes
A16: Percentage | B16: =B14/B13 -> 0.4324 | G16: water | H16: -53.5 | I16: yes
G17: hp | H17: -1.8 | I17: yes
A18: Mortgage | D18: holiday | G18: DISHWASHER | H18: -5 | I18: yes
A19: Main | B19: 151455.79 | G19: fran money for card | H19: -800 | I19: yes | J19: f1
A20: Extra | B20: 80139.8 | G20: tesco mobiles | H20: -28 | I20: yes | J20: f2
A21: Total Due | B21: =SUM(B19:B20) -> 231595.59 | G21: green belt | H21: -14.99 | I21: yes
A22: H2B paybak | B22: =B23*0.2 -> 92000 | D22: JL092865B | G22: food petrol | H22: -900 | I22: yes | J22: f1
A23: Sold Price | B23: 460000 | G23: phone | H23: -11 | I23: yes
A24: Equity | B24: =B23-SUM(B21:B22) -> 136404.41 | G24: fran credit | H24: -314 | I24: yes | J24: f1
G25: dental | H25: -20 | I25: yes
G26: car insurance lv | H26: -27.7 | I26: yes
G27: child benefit shit | H27: -80 | I27: yes | J27: f1
G28: zoom | H28: -18 | I28: yes
G29: gym | H29: -33 | I29: yes | J29: f2
A30: NW | G30: boiler | H30: -14.3 | I30: yes
A31: 1104841580 | G31: service | H31: -35 | I31: yes | J31: f1
G32: matt | H32: -100 | I32: yes
G33: pocket money | H33: -20 | I33: yes
G34: help to by | H34: -130 | I34: yes
G35: lunch | H35: -20 | I35: yes | J35: f2
G36: credit card | H36: -189 | I36: yes
G37: applee | H37: -11 | I37: yes
G38: green waste | H38: -8 | I38: yes
G39: half term | H39: -100 | I39: yes | J39: f1
G40: willows wardrobe | H40: -210 | I40: yes
...

Sheet april25
A1: Money | D1: Savings Account | G1: Name | H1: Value | I1: Paid? | J1: Who
A2: Paid | B2: 5155.73 | D2: Rainy Day 🌧️ | E2: 75 | G2: Mortgage | H2: -1268.67 | I2: yes
A3: Taken Already | B3: =SUMIF(I2:I47,"Yes*",H2:H47) -> -5218.15 | G3: isa | H3: -270 | I3: yes | J3: s
A4: Balance | B4: 27.57 | D4: Dental 🪥 | E4: 50 | G4: LifeInsurance/aviva | H4: -37 | I4: yes
A5: To Be Taken | B5: =SUMIF(I2:I47,"No",H2:H47) -> 0 | D5: Vet Fund 😺 | E5: 550 | G5: HouseInsurance - Tesco | H5: -39 | I5: yes
A6: Total | B6: =B5+B4 -> 27.57 | G6: TvLicence | H6: -15 | I6: yes
A7: Francesca pt 1 | B7: =SUMIF(J2:J47,"f1",H2:H47) -> -2383 | D7: furnitiure | G7: Gas/Electric | H7: -155 | I7: yes
A8: Francesca pt 2 | B8: =SUMIF(J2:J47,"f2",H2:H47) -> -81 | D8: Savings | G8: pet insur | H8: -50 | I8: yes | J8: s
A9: Matt | B9: =SUMIF(J2:J47,"",H2:H47) -> -2434.15 | G9: spotoify | H9: -20 | I9: yes
A10: Savings | B10: =SUMIF(J2:J47,"s",H2:H47) -> -320 | D10: TAX | G10: rumpus food | H10: -25 | I10: yes
D11: Saving Total | E11: =SUM(E2:E10) -> 675 | I11: no
G12: amazon | H12: -8.99 | I12: yes
A13: Emergency Target | B13: 10000 | D13: francesca Isa | E13: 4324 | G13: council tax | H13: -239 | I13: yes
A14: Emergency Fund | B14: 4324 | D14: FRANNYS MONEY | G14: water | H14: -13 | I14: yes
A15: Emergency Left | G15: window clean | H15: -10 | I15: yes
A16: Percentage | B16: =B14/B13 -> 0.4324 | G16: water | H16: -53.3 | I16: yes
G17: hp | H17: -1.5 | I17: yes
A18: Mortgage | D18: holiday | G18: DISHWASHER | H18: -5 | I18: yes
A19: Main | B19: 153458.32 | G19: fran money for card | H19: -1000 | I19: yes | J19: f1
A20: Extra | B20: 81199.44 | G20: tesco mobiles | H20: -28 | I20: yes | J20: f2
A21: Total Due | B21: =SUM(B19:B20) -> 234657.76 | G21: green belt | H21: -14.99 | I21: yes
A22: H2B paybak | B22: =B23*0.2 -> 90000 | D22: JL092865B | G22: food petrol | H22: -1150 | I22: yes | J22: f1
A23: Sold Price | B23: 450000 | G23: phone | H23: -11 | I23: yes
A24: Equity | B24: =B23-SUM(B21:B22) -> 125342.24 | G24: greenbelt | H24: -14 | I24: yes
G25: dental | H25: -20 | I25: yes
G26: car insurance lv | H26: -27.7 | I26: yes
G27: child benefit shit | H27: -60 | I27: yes | J27: f1
G28: zoom | H28: -18 | I28: yes
G29: gym | H29: -33 | I29: yes | J29: f2
A30: NW | G30: boiler | H30: -12 | I30: yes
A31: 1104841580 | G31: service | H31: -35 | I31: yes | J31: f1
G32: matt | H32: -100 | I32: yes
G33: pocket money | H33: -20 | I33: yes
G34: help to by | H34: -142 | I34: yes
G35: lunch | H35: -20 | I35: yes | J35: f2
G36: credit card | H36: -138 | I36: yes | J36: f1
G37: applee | H37: -11 | I37: yes
G38: green waste | H38: -8 | I38: yes
G39: dishwasher | H39: -5 | I39: yes
G40: fran money for card | H40: -140 | I40: yes
...

Sheet mar25
A1: Money | D1: Savings Account | G1: Name | H1: Value | I1: Paid? | J1: Who
A2: Paid | B2: 5140.92 | D2: Rainy Day 🌧️ | E2: 100 | G2: Mortgage | H2: -1268.67 | I2: yes
A3: Taken Already | B3: =SUMIF(I2:I47,"Yes*",H2:H47) -> -5590.16 | D3: Francesca Birthday | G3: isa | H3: -320 | I3: yes | J3: s
A4: Balance | B4: 48.01 | D4: Dental 🪥 | E4: 80 | G4: LifeInsurance/aviva | H4: -37 | I4: yes
A5: To Be Taken | B5: =SUMIF(I2:I47,"No",H2:H47) -> -19 | D5: Vet Fund 😺 | E5: 500 | G5: HouseInsurance - Tesco | H5: -39 | I5: yes
A6: Total | B6: =B5+B4 -> 29.01 | D6: matt | G6: TvLicence | H6: -15 | I6: yes
A7: Francesca pt 1 | B7: =SUMIF(J2:J47,"f1",H2:H47) -> -1920 | D7: oslo | E7: 150 | G7: Gas/Electric | H7: -155 | I7: yes
A8: Francesca pt 2 | B8: =SUMIF(J2:J47,"f2",H2:H47) -> -226 | D8: TRAIN TICKETS OSLO | G8: pet insur | H8: -50 | I8: yes | J8: s
A9: Matt | B9: =SUMIF(J2:J47,"",H2:H47) -> -3018.16 | D9: money for fran | G9: spotoify | H9: -20 | I9: yes
A10: Savings | B10: =SUMIF(J2:J47,"s",H2:H47) -> -445 | D10: TAX | E10: 162 | G10: rumpus food | H10: -55 | I10: yes | J10: s
D11: Saving Total | E11: =SUM(E2:E10) -> 992 | G11: FRAN BIRTHDAAY | H11: -135 | I11: yes
G12: amazon | H12: -8.99 | I12: yes
A13: Emergency Target | B13: 10000 | D13: francesca Isa | E13: 3917.77 | G13: council tax | H13: -239 | I13: yes
A14: Emergency Fund | B14: 3917.77 | D14: FRANNYS MONEY | G14: water | H14: -13 | I14: yes
A15: Emergency Left | G15: window clean | H15: -10 | I15: yes
A16: Percentage | B16: =B14/B13 -> 0.391777 | D16: nor holiday fund in matt | E16: 800 | G16: water | H16: -31.5 | I16: yes
G17: hp | H17: -1.5 | I17: yes
A18: Mortgage | D18: holiday | G18: DISHWASHER | H18: -5 | I18: no
A19: Main | B19: 153458.32 | G19: fran money for card | H19: -800 | I19: yes | J19: f1
A20: Extra | B20: 81199.44 | G20: tesco mobiles | H20: -28 | I20: yes | J20: f2
A21: Total Due | B21: =SUM(B19:B20) -> 234657.76 | G21: matt credit | H21: -32.5 | I21: yes
A22: H2B paybak | B22: =B23*0.2 -> 90000 | D22: JL092865B | G22: food petrol | H22: -900 | I22: yes | J22: f1
A23: Sold Price | B23: 450000 | G23: phone | H23: -11 | I23: yes
A24: Equity | B24: =B23-SUM(B21:B22) -> 125342.24 | D24: money for car | G24: greenbelt | H24: -14 | I24: no
G25: dental | H25: -20 | I25: yes | J25: s
G26: car insurance lv | H26: -31 | I26: yes
G27: child benefit shit | H27: -80 | I27: yes | J27: f1
G28: zoom | H28: -18 | I28: yes
G29: gym | H29: -33 | I29: yes | J29: f2
A30: NW | G30: boiler | H30: -12 | I30: yes
A31: 1104841580 | G31: SERVICE MONEY | H31: -165 | I31: yes | J31: f2
G32: matt | H32: -100 | I32: yes
G33: pocket money | H33: -20 | I33: yes
G34: help to by | H34: -127 | I34: yes
G35: lunch | I35: no | J35: f1
G36: conv | I36: no
G37: applee | H37: -11 | I37: yes
G38: alison | H38: -120 | I38: yes
G39: 5 week month | H39: -100 | I39: yes
G40: easter | H40: -30 | I40: yes
...

Sheet feb25
A1: Money | D1: Savings Account | G1: Name | H1: Value | I1: Paid? | J1: Who
A2: Paid | B2: 5346.82 | D2: Rainy Day 🌧️ | E2: 100 | G2: Mortgage | H2: -1268.67 | I2: yes
A3: Taken Already | B3: =SUMIF(I2:I47,"Yes*",H2:H47) -> -5598.73 | D3: Francesca Birthday | E3: 300 | I3: no | J3: s
A4: Balance | B4: 13.38 | D4: Dental 🪥 | E4: 89 | G4: LifeInsurance/aviva | H4: -37 | I4: yes
A5: To Be Taken | B5: =SUMIF(I2:I47,"No",H2:H47) -> 0 | D5: Vet Fund 😺 | E5: 550 | G5: HouseInsurance - Tesco | H5: -39 | I5: yes
A6: Total | B6: =B5+B4 -> 13.38 | D6: Willow Dinner | E6: 215 | G6: TvLicence | H6: -15 | I6: yes
A7: Francesca pt 1 | B7: =SUMIF(J2:J47,"f1",H2:H47) -> -1810 | D7: alison | G7: Gas/Electric | H7: -155 | I7: yes
A8: Francesca pt 2 | B8: =SUMIF(J2:J47,"f2",H2:H47) -> -61 | D8: willow bday | E8: 150 | G8: pet insur | H8: -50 | I8: yes | J8: s
A9: Matt | B9: =SUMIF(J2:J47,"",H2:H47) -> -3602.73 | D9: my face | E9: 220 | G9: spotoify | H9: -20 | I9: yes
A10: Savings | B10: =SUMIF(J2:J47,"s",H2:H47) -> -125 | D10: Train | E10: 63 | G10: rumpus food | H10: -55 | I10: yes | J10: s
D11: Saving Total | E11: =SUM(E2:E10) -> 1687 | G11: netflix | I11: no
G12: amazon | H12: -8.99 | I12: yes
A13: Emergency Target | B13: 10000 | D13: francesca Isa | E13: 5145.97 | G13: council tax | H13: -225 | I13: yes
A14: Emergency Fund | B14: =E12+E13 -> 5145.97 | D14: FRANNYS MONEY | E14: 1175 | G14: water | H14: -13 | I14: yes
A15: Emergency Left | B15: =B13-B14 -> 4854.03 | G15: window clean | H15: -10 | I15: yes | J15: f1
A16: Percentage | B16: =B14/B13 -> 0.514597 | D16: nor holiday fund in matt | E16: 799.91 | G16: water | H16: -31.5 | I16: yes
G17: hp | H17: -1.5 | I17: yes
A18: Mortgage | G18: DISHWASHER | H18: -5 | I18: yes
A19: Main | B19: 152191.25 | G19: fran money for card | H19: -800 | I19: yes | J19: f1
A20: Extra | B20: 80528.96 | G20: tesco mobiles | H20: -28 | I20: yes | J20: f2
A21: Total Due | B21: =SUM(B19:B20) -> 232720.21 | G21: credit card | H21: -20 | I21: yes | J21: f1
A22: H2B paybak | B22: =B23*0.2 -> 95000 | G22: food petrol | H22: -900 | I22: yes | J22: f1
A23: Sold Price | B23: 475000 | G23: phone | H23: -11 | I23: yes
A24: Equity | B24: =B23-SUM(B21:B22) -> 147279.79 | G24: greenbelt | H24: -7.6 | I24: yes
G25: dental | H25: -20 | I25: yes | J25: s
G26: car insurance lv | H26: -31 | I26: yes
G27: child benefit shit | H27: -80 | I27: yes | J27: f1
G28: zoom | H28: -18 | I28: yes
A29: JL092865B | G29: gym | H29: -33 | I29: yes | J29: f2
A30: NW | G30: boiler | H30: -12 | I30: yes
A31: 1104841580 | G31: service | H31: -33 | I31: yes
G32: matt | H32: -100 | I32: yes
G33: pocket money | H33: -20 | I33: yes
G34: help to by | H34: -127 | I34: yes
G35: lunch | H35: -20 | I35: yes
G36: backpack | H36: -23 | I36: yes
G37: appl | H37: -11 | I37: yes
G38: matt credit card | H38: -413.46 | I38: yes
G39: face | H39: -220 | I39: yes
G40: washing machine | H40: -332.67 | I40: yes
...

Sheet jan25
A1: Money | D1: Savings Account | G1: Name | H1: Value | I1: Paid? | J1: Who | K1: Category
A2: Paid | B2: 5188.49 | G2: Mortgage | H2: -1261.98 | I2: yes | K2: House
A3: Taken Already | B3: =SUMIF(I2:I47,"Yes*",H2:H47) -> -5326.46 | D3: Rainy Day 🌧️ | E3: 50 | G3: dad paint | H3: -350 | I3: yes | J3: s | K3: Savings
A4: Balance | B4: 4.73 | D4: Francesca Birthday | E4: 300 | G4: LifeInsurance/aviva | H4: -37 | I4: yes | K4: Insurance
A5: To Be Taken | B5: =SUMIF(I2:I47,"No",H2:H47) -> 0 | D5: Dental 🪥 | G5: HouseInsurance - Tesco | H5: -39 | I5: yes | K5: Insurance
A6: Total | B6: =B5+B4 -> 4.73 | D6: Vet Fund 😺 | E6: 530 | G6: TvLicence | H6: -15 | I6: yes | K6: HouseBill
A7: Francesca pt 1 | B7: =SUMIF(J2:J47,"f1",H2:H47) -> -2025 | D7: Willow Dinner | E7: 200 | G7: Gas/Electric | H7: -155 | I7: yes | K7: HouseBill
A8: Francesca pt 2 | B8: =SUMIF(J2:J47,"f2",H2:H47) -> -61 | D8: kettle | E8: 221 | G8: pet insur | H8: -50 | I8: yes | J8: s | K8: Insurance
A9: Matt | B9: =SUMIF(J2:J47,"",H2:H47) -> -2773.46 | D9: willow bday | E9: 150 | G9: spotoify | H9: -20 | I9: yes | K9: Subscription
A10: Savings | B10: =SUMIF(J2:J47,"s",H2:H47) -> -467 | G10: rumpus food | H10: -67 | I10: yes | J10: s | K10: Savings
D11: Saving Total | E11: =SUM(E2:E10) -> 1451 | G11: netflix | H11: -4.99 | I11: yes | K11: Subscription
D12: Emergency Fund | G12: amazon | H12: -8.99 | I12: yes | K12: Subscription
A13: Emergency Target | B13: 10000 | D13: francesca Isa | E13: 5145.97 | G13: council tax | H13: -225 | I13: yes | K13: HouseBill
A14: Emergency Fund | B14: =E12+E13 -> 5145.97 | D14: FRANNYS MONEY | E14: 1455 | G14: water | H14: -13 | I14: yes | K14: HouseBill
A15: Emergency Left | B15: =B13-B14 -> 4854.03 | G15: window clean | I15: no | K15: HouseBill
A16: Percentage | B16: =B14/B13 -> 0.514597 | D16: nor holiday fund in matt | E16: 595 | G16: water | H16: -31.5 | I16: yes | K16: HouseBill
G17: hp | H17: -1.5 | I17: yes | K17: Subscription
A18: Mortgage | D18: holiday | G18: DISHWASHER | H18: -5 | I18: yes | K18: Insurance
A19: Main | B19: 153458.32 | G19: fran money for card | H19: -800 | I19: yes | J19: f1 | K19: Francesca
A20: Extra | B20: 81199.44 | G20: tesco mobiles | H20: -28 | I20: yes | J20: f2 | K20: Mobile
A21: Total Due | B21: =SUM(B19:B20) -> 234657.76 | G21: credit card | H21: -245 | I21: yes | J21: f1 | K21: Francesca
A22: H2B paybak | B22: =B23*0.2 -> 90000 | D22: JL092865B | G22: food petrol | H22: -900 | I22: yes | J22: f1 | K22: Food
A23: Sold Price | B23: 450000 | G23: phone | H23: -11 | I23: yes | K23: Mobile
A24: Equity | B24: =B23-SUM(B21:B22) -> 125342.24 | G24: greenbelt | H24: -7.6 | I24: yes | K24: HouseBill
G25: next | I25: no | J25: s | K25: Savings
G26: car insurance lv | H26: -31 | I26: yes | K26: Insurance
G27: child benefit shit | H27: -80 | I27: yes | J27: f1 | K27: Francesca
G28: zoom | H28: -18 | I28: yes | K28: HouseBill
G29: gym | H29: -33 | I29: yes | J29: f2 | K29: Francesca
A30: NW | G30: boiler | H30: -12 | I30: yes | K30: HouseBill
A31: 1104841580 | G31: service | H31: -33 | I31: yes | K31: Savings
G32: matt | H32: -100 | I32: yes | K32: Spending
G33: pocket money | H33: -20 | I33: yes | K33: Medical
G34: help to by | H34: -127 | I34: yes | K34: House
G35: lunch | H35: -20 | I35: yes | K35: Savings
G36: sky sports | H36: -27 | I36: yes | K36: Francesca
G37: dental | H37: -20 | I37: yes | K37: Francesca
G38: matt credit card | H38: -35.9 | I38: yes
G39: beth | H39: -40 | I39: yes
G40: PAINT | H40: -140 | I40: yes
...

Sheet minium 25
A1: Money | D1: Savings Account | G1: Name | H1: Value | I1: Paid? | J1: Who | K1: fixed
A2: Paid | B2: 5225 | D2: Rainy Day 🌧️ | E2: 80 | G2: Mortgage | H2: -1117 | I2: no | K2: yes
A3: Taken Already | B3: =SUMIF(I2:I47,"Yes*",H2:H47) -> 0 | G3: stock and share | H3: -140 | I3: no | J3: s
A4: Balance | B4: 5225 | D4: Dental 🪥 | E4: 110 | G4: LifeInsurance/aviva | H4: -39 | I4: no | K4: yes
A5: To Be Taken | B5: =SUMIF(I2:I47,"No",H2:H47) -> -4627.67 | D5: Vet Fund 😺 | E5: 560 | G5: HouseInsurance - Tesco | H5: -39 | I5: no | K5: yes
A6: Total | B6: =B5+B4 -> 597.33 | G6: TvLicence | H6: -17 | I6: no | K6: yes
A7: Francesca pt 1 | B7: =SUMIF(J2:J47,"f1",H2:H47) -> -2032.99 | D7: furnitiure | G7: Gas/Electric | H7: -200 | I7: no | K7: yes
A8: Francesca pt 2 | B8: =SUMIF(J2:J47,"f2",H2:H47) -> -181 | D8: Savings | G8: pet insur | H8: -40 | I8: no | J8: s | K8: yes
A9: Matt | B9: =SUMIF(J2:J47,"",H2:H47) -> -2233.68 | G9: spotoify | H9: -20 | I9: no
A10: Savings | B10: =SUMIF(J2:J47,"s",H2:H47) -> -180 | D10: TAX | G10: rumpus food | H10: -55 | I10: no
D11: Saving Total | E11: =SUM(E2:E10) -> 750 | G11: rumpus arun vet | H11: -7.99 | I11: no | J11: f1 | K11: yes
G12: amazon | H12: -8.99 | I12: no
A13: Emergency Target | B13: 10000 | D13: francesca Isa | E13: 4324 | G13: council tax | H13: -239 | I13: no | K13: y
A14: Emergency Fund | B14: 4324 | D14: FRANNYS MONEY | G14: water | H14: -26 | I14: no | K14: y
A15: Emergency Left | G15: window clean | H15: -10 | I15: no
A16: Percentage | B16: =B14/B13 -> 0.4324 | G16: water | H16: -58 | I16: no | K16: y
G17: hp | H17: -1.5 | I17: no
A18: Mortgage | D18: holiday | G18: DISHWASHER | H18: -5 | I18: no
A19: Main | B19: 151455.79 | G19: fran money for card | H19: -800 | I19: no | J19: f1 | K19: y
A20: Extra | B20: 80139.8 | G20: tesco mobiles | H20: -28 | I20: no | J20: f2 | K20: y
A21: Total Due | B21: =SUM(B19:B20) -> 231595.59 | G21: green belt | H21: -14.99 | I21: no | K21: y
A22: H2B paybak | B22: =B23*0.2 -> 92000 | D22: JL092865B | G22: food petrol | H22: -930 | I22: no | J22: f1 | K22: y
A23: Sold Price | B23: 460000 | G23: willow bday | I23: no
A24: Equity | B24: =B23-SUM(B21:B22) -> 136404.41 | G24: botox | H24: -70 | I24: no | J24: f1
G25: dental | H25: -20 | I25: no
G26: car insurance lv | H26: -27.7 | I26: no | K26: y
G27: child benefit shit | H27: -90 | I27: no | J27: f1
G28: zoom | H28: -18 | I28: no
G29: 5 week month | H29: -133 | I29: no | J29: f2
A30: NW | G30: boiler | H30: -14.5 | I30: no
A31: 1104841580 | G31: service | H31: -35 | I31: no | J31: f1
G32: matt | H32: -60 | I32: no
G33: pocket money | H33: -25 | I33: no
G34: help to by | H34: -130 | I34: no
G35: lunch | H35: -20 | I35: no | J35: f2
G36: nails | H36: -100 | I36: no | J36: f1
G37: christma | H37: -50 | I37: no
G38: green waste | H38: -8 | I38: no
I39: no
G40: gym | H40: -30 | I40: no
...

Sheet dec24
A1: Money | D1: Savings Account | G1: Name | H1: Value | I1: Paid? | J1: Who | K1: Category
A2: Paid | B2: 5176.06 | G2: Mortgage | H2: -1268.67 | I2: yes | K2: House
A3: Taken Already | B3: =SUMIF(I2:I47,"Yes*",H2:H47) -> -5152.25 | D3: Rainy Day 🌧️ | E3: 50 | G3: botox | H3: -210 | I3: yes | J3: s | K3: Savings
A4: Balance | B4: 19.45 | D4: health insure | E4: 100 | G4: LifeInsurance/aviva | H4: -37 | I4: yes | K4: Insurance
A5: To Be Taken | B5: =SUMIF(I2:I47,"No",H2:H47) -> -16 | D5: Dental 🪥 | E5: 100 | G5: HouseInsurance - Tesco | H5: -39 | I5: yes | K5: Insurance
A6: Total | B6: =B5+B4 -> 3.45 | D6: Vet Fund 😺 | E6: 580 | G6: TvLicence | H6: -15 | I6: yes | K6: HouseBill
A7: Francesca pt 1 | B7: =SUMIF(J2:J47,"f1",H2:H47) -> -2400 | D7: face | E7: 370 | G7: Gas/Electric | H7: -155 | I7: yes | K7: HouseBill
A8: Francesca pt 2 | B8: =SUMIF(J2:J47,"f2",H2:H47) -> -171 | D8: phone | G8: pet insur | H8: -50 | I8: yes | J8: s | K8: Insurance
A9: Matt | B9: =SUMIF(J2:J47,"",H2:H47) -> -2287.25 | D9: Christmas 🎄 | G9: spotoify | H9: -20 | I9: yes | K9: Subscription
A10: Savings | B10: =SUMIF(J2:J47,"s",H2:H47) -> -310 | D10: xmas trip | G10: rumpus food | H10: -30 | I10: yes | J10: f2 | K10: Savings
D11: Saving Total | E11: =SUM(E2:E10) -> 1200 | G11: netflix | H11: -4.99 | I11: yes | K11: Subscription
D12: Emergency Fund | G12: breakdown | H12: -38 | I12: yes | K12: Subscription
A13: Emergency Target | B13: 12000 | D13: francesca Isa | E13: 5135.7 | G13: council tax | H13: -225 | I13: yes | K13: HouseBill
A14: Emergency Fund | B14: =E12+E13 -> 5135.7 | D14: LV handbag fund | E14: 1453 | G14: water | H14: -13 | I14: yes | K14: HouseBill
A15: Emergency Left | B15: =B13-B14 -> 6864.3 | D15: car fix fund | G15: window clean | I15: no | K15: HouseBill
A16: Percentage | B16: =B14/B13 -> 0.427975 | D16: nor holiday fund in matt | E16: 445 | G16: water | H16: -31.5 | I16: yes | K16: HouseBill
G17: hp | H17: -1.5 | I17: yes | K17: Subscription
A18: Mortgage | D18: holiday | G18: DISHWASHER | H18: -5 | I18: no | K18: Insurance
A19: Main | B19: 152053.12 | G19: fran money for card | H19: -1000 | I19: yes | J19: f1 | K19: Francesca
A20: Extra | B20: 80455.88 | G20: tesco mobiles | H20: -28 | I20: yes | J20: f2 | K20: Mobile
A21: Total Due | B21: =SUM(B19:B20) -> 232509 | G21: credit card | H21: -40 | I21: yes | J21: f1 | K21: Francesca
A22: H2B paybak | B22: =B23*0.2 -> 90000 | D22: JL092865B | G22: food petrol | H22: -1100 | I22: yes | J22: f1 | K22: Food
A23: Sold Price | B23: 450000 | G23: phone | H23: -11 | I23: no | K23: Mobile
A24: Equity | B24: =B23-SUM(B21:B22) -> 127491 | G24: greenbelt | H24: -7.6 | I24: yes | K24: HouseBill
G25: cat food | H25: -30 | I25: yes | J25: s | K25: Savings
G26: car insurance lv | H26: -31 | I26: yes | K26: Insurance
G27: child benefit shit | H27: -80 | I27: yes | J27: f1 | K27: Francesca
G28: zoom | H28: -18 | I28: yes | K28: HouseBill
G29: gym | H29: -33 | I29: yes | J29: f2 | K29: Francesca
A30: NW | G30: boiler | H30: -12 | I30: yes | K30: HouseBill
A31: 1104841580 | G31: service | H31: -33 | I31: yes | K31: Savings
G32: matt | H32: -50 | I32: yes | K32: Spending
G33: pocket money | H33: -20 | I33: yes | J33: s | K33: Medical
G34: help to by | H34: -127 | I34: yes | K34: House
G35: christmas hols | H35: -180 | I35: yes | J35: f1 | K35: Savings
G36: sky sports | H36: -27 | I36: yes | K36: Francesca
G37: new year | H37: -80 | I37: yes | J37: f2 | K37: Francesca
G38: bartley | H38: -108 | I38: yes
G39: amazon | H39: -8.99 | I39: yes
I40: no
...

Sheet nov24
A1: Money | D1: Savings Account | G1: Name | H1: Value | I1: Paid? | J1: Who | K1: Category
A2: Paid | B2: 5237.78 | G2: Mortgage | H2: -1268.67 | I2: yes | K2: House
A3: Taken Already | B3: =SUMIF(I2:I47,"Yes*",H2:H47) -> -5301.39 | D3: Rainy Day 🌧️ | E3: 100 | G3: plummer | H3: -250 | I3: yes | J3: s | K3: Savings
A4: Balance | B4: 38.48 | D4: health insure | E4: 100 | G4: LifeInsurance/aviva | H4: -37 | I4: yes | K4: Insurance
A5: To Be Taken | B5: =SUMIF(I2:I47,"No",H2:H47) -> -31 | D5: Dental 🪥 | E5: 100 | G5: HouseInsurance - Tesco | H5: -35 | I5: yes | K5: Insurance
A6: Total | B6: =B5+B4 -> 7.48 | D6: Vet Fund 😺 | E6: 550 | G6: TvLicence | H6: -15 | I6: yes | K6: HouseBill
A7: Francesca pt 1 | B7: =SUMIF(J2:J47,"f1",H2:H47) -> -1966 | D7: face money | E7: 160 | G7: Gas/Electric | H7: -155 | I7: yes | K7: HouseBill
A8: Francesca pt 2 | B8: =SUMIF(J2:J47,"f2",H2:H47) -> -61 | D8: phone | G8: pet insur | H8: -80 | I8: yes | J8: s | K8: Insurance
A9: Matt | B9: =SUMIF(J2:J47,"",H2:H47) -> -2855.39 | D9: Christmas 🎄 | G9: spotoify | H9: -20 | I9: yes | K9: Subscription
A10: Savings | B10: =SUMIF(J2:J47,"s",H2:H47) -> -450 | D10: xmas trip | G10: health insurance | H10: -100 | I10: yes | J10: s | K10: Savings
D11: Saving Total | E11: =SUM(E2:E10) -> 1010 | G11: netflix | H11: -4.99 | I11: yes | K11: Subscription
D12: Emergency Fund | G12: zoom | H12: -18 | I12: yes | K12: Subscription
A13: Emergency Target | B13: 12000 | D13: francesca Isa | E13: 5111.07 | G13: council tax | H13: -225 | I13: yes | K13: HouseBill
A14: Emergency Fund | B14: =E12+E13 -> 5111.07 | D14: LV handbag fund | E14: 1345.57 | G14: water | H14: -13 | I14: yes | K14: HouseBill
A15: Emergency Left | B15: =B13-B14 -> 6888.93 | D15: car fix fund | E15: 1370 | G15: window clean | H15: -10 | I15: yes | K15: HouseBill
A16: Percentage | B16: =B14/B13 -> 0.4259225 | G16: water | H16: -31.5 | I16: yes | K16: HouseBill
G17: hp | H17: -1.5 | I17: yes | K17: Subscription
A18: Mortgage | G18: DISHWASHER | H18: -5 | I18: yes | K18: Insurance
A19: Main | B19: 152415.81 | G19: fran money for card | H19: -800 | I19: yes | J19: f1 | K19: Francesca
A20: Extra | B20: 80647.8 | G20: tesco mobiles | H20: -28 | I20: yes | J20: f2 | K20: Mobile
A21: Total Due | B21: =SUM(B19:B20) -> 233063.61 | G21: credit card | H21: -186 | I21: yes | J21: f1 | K21: Francesca
A22: H2B paybak | B22: =B23*0.2 -> 90000 | G22: food petrol | H22: -900 | I22: yes | J22: f1 | K22: Food
A23: Sold Price | B23: 450000 | G23: phone | H23: -11 | I23: yes | K23: Mobile
A24: Equity | B24: =B23-SUM(B21:B22) -> 126936.39 | G24: greenbelt | H24: -7.6 | I24: yes | K24: HouseBill
G25: next | I25: no | J25: s | K25: Savings
A26: JL092865B | G26: car insurance lv | H26: -31 | I26: yes | K26: Insurance
G27: child benefit shit | H27: -80 | I27: yes | J27: f1 | K27: Francesca
G28: zoom | H28: -18 | I28: no | K28: HouseBill
G29: gym | H29: -33 | I29: yes | J29: f2 | K29: Francesca
A30: NW | G30: boiler | H30: -12 | I30: yes | K30: HouseBill
A31: 1104841580 | G31: service | H31: -33 | I31: yes | K31: Savings
G32: matt | H32: -100 | I32: yes | K32: Spending
G33: dental | H33: -20 | I33: yes | J33: s | K33: Medical
G34: help to by | H34: -127 | I34: yes | K34: House
G35: christmas frank | I35: no | K35: Savings
G36: sky sports | H36: -27 | I36: yes | K36: Francesca
G37: christmas | H37: -100 | I37: yes | K37: Francesca
G38: christmas food | H38: -150 | I38: yes
G39: matt credit | H39: -236.13 | I39: yes
G40: matt christmas | H40: -150 | I40: yes
...

Sheet oct24
A1: Money | D1: Savings Account | G1: Name | H1: Value | I1: Paid? | J1: Who | K1: Category
A2: Paid | B2: 5147.97 | G2: Mortgage | H2: -1268.67 | I2: yes | K2: House
A3: Taken Already | B3: =SUMIF(I2:I47,"Yes*",H2:H47) -> -5776.4 | D3: Rainy Day 🌧️ | E3: 100 | G3: botox | H3: -230 | I3: yes | K3: Savings
A4: Balance | B4: 56.22 | D4: HEALTH INSURANCE | E4: 100 | G4: LifeInsurance/aviva | H4: -37 | I4: yes | K4: Insurance
A5: To Be Taken | B5: =SUMIF(I2:I47,"No",H2:H47) -> 0 | D5: Dental 🪥 | E5: 80 | G5: HouseInsurance - Tesco | H5: -39 | I5: yes | K5: Insurance
A6: Total | B6: =B5+B4 -> 56.22 | D6: Vet Fund 😺 | E6: 570 | G6: TvLicence | H6: -15 | I6: yes | K6: HouseBill
A7: Francesca pt 1 | B7: =SUMIF(J2:J47,"f1",H2:H47) -> -1700 | D7: next month | G7: Gas/Electric | H7: -155 | I7: yes | K7: HouseBill
A8: Francesca pt 2 | B8: =SUMIF(J2:J47,"f2",H2:H47) -> -28 | D8: phone | G8: pet insur | H8: -50 | I8: yes | J8: s | K8: Insurance
A9: Matt | B9: =SUMIF(J2:J47,"",H2:H47) -> -3978.4 | D9: Christmas francesca🎄 | E9: 73 | G9: spotoify | H9: -20 | I9: yes | K9: Subscription
A10: Savings | B10: =SUMIF(J2:J47,"s",H2:H47) -> -70 | G10: zoom | H10: -18 | I10: yes | K10: Savings
D11: Saving Total | E11: =SUM(E2:E10) -> 923 | G11: netflix | H11: -4.99 | I11: yes | K11: Subscription
D12: Emergency Fund | G12: franny phone | H12: -80 | I12: yes | K12: Subscription
A13: Emergency Target | B13: 12000 | D13: francesca Isa | E13: 5095.24 | G13: council tax | H13: -225 | I13: yes | K13: HouseBill
A14: Emergency Fund | B14: =E12+E13 -> 5095.24 | D14: bag | E14: 1341.51 | G14: water | H14: -13 | I14: yes | K14: HouseBill
A15: Emergency Left | B15: =B13-B14 -> 6904.76 | D15: car fix fund | E15: 1270 | G15: window clean | H15: -10 | I15: yes | K15: HouseBill
A16: Percentage | B16: =B14/B13 -> 0.42460333 | G16: water | H16: -31.5 | I16: yes | K16: HouseBill
G17: hp | H17: -1.5 | I17: yes | K17: Subscription
A18: Mortgage | D18: holiday | G18: DISHWASHER | H18: -5 | I18: yes | K18: Insurance
A19: Main | B19: 153458.32 | G19: fran money for card | H19: -185 | I19: yes | J19: f1 | K19: Francesca
A20: Extra | B20: 81199.44 | G20: tesco mobiles | H20: -28 | I20: yes | J20: f2 | K20: Mobile
A21: Total Due | B21: =SUM(B19:B20) -> 234657.76 | G21: credit card | H21: -85 | I21: yes | J21: f1 | K21: Francesca
A22: H2B paybak | B22: =B23*0.2 -> 90000 | D22: JL092865B | G22: food petrol | H22: -1100 | I22: yes | J22: f1 | K22: Food
A23: Sold Price | B23: 450000 | G23: phone | H23: -11 | I23: yes | K23: Mobile
A24: Equity | B24: =B23-SUM(B21:B22) -> 125342.24 | G24: greenbelt | H24: -7.6 | I24: yes | K24: HouseBill
G25: next | H25: -30 | I25: yes | K25: Savings
G26: car insurance lv | H26: -31 | I26: yes | K26: Insurance
G27: child benefit shit | H27: -80 | I27: yes | J27: f1 | K27: Francesca
G28: zoom | H28: -18 | I28: yes | K28: HouseBill
G29: credit card | H29: -657.22 | I29: yes | K29: Francesca
A30: NW | G30: boiler | H30: -12 | I30: yes | K30: HouseBill
A31: 1104841580 | G31: service | H31: -33 | I31: yes | K31: Savings
G32: matt | H32: -100 | I32: yes | K32: Spending
G33: dental | H33: -20 | I33: yes | J33: s | K33: Medical
G34: help to by | H34: -127 | I34: yes | K34: House
G35: half term | H35: -150 | I35: yes | K35: Savings
G36: sky sports | H36: -27 | I36: yes | K36: Francesca
G37: klana | H37: -620.92 | I37: yes | K37: Francesca
G38: isa | H38: -250 | I38: yes | J38: f1
I39: no
I40: no
...

Sheet may24
A1: Money | D1: Savings Account | G1: Name | H1: Value | I1: Paid? | J1: Who
A2: Paid | B2: 4954.81 | D2: holday fund | E2: 335 | G2: Mortgage | H2: -1268.67 | I2: yes
A3: Taken Already | B3: =SUMIF(I2:I28,"Yes*",H2:H28) -> -4331.95 | D3: rainy day fund | E3: 111 | G3: Car | H3: -244.8 | I3: yes | J3: f2
A4: Balance | B4: 53.12 | D4: service fund | E4: 250 | G4: LifeInsurance/aviva | H4: -33 | I4: yes
A5: To Be Taken | B5: =SUMIF(I2:I37,"No",H2:H37) -> -10 | D5: dental | E5: 95 | G5: HouseInsurance - Tesco | H5: -39 | I5: yes
A6: Total | B6: =B5+B4 -> 43.12 | D6: rumpus vet fund | E6: 355 | G6: TvLicence | H6: -13.2 | I6: yes
A7: Francesca pt 1 | B7: =SUMIF(J2:J32,"f1",H2:H32) -> -1805 | D7: coffee machine | E7: 275 | G7: Gas/Electric | H7: -155 | I7: yes
A8: Francesca pt 2 | B8: =SUMIF(J2:J32,"f2",H2:H32) -> -304.8 | D8: cat sitter AP+AUG | E8: 90 | G8: pet insur | H8: -40 | I8: yes
A9: Matt | B9: =SUMIF(J2:J32,"",H2:H32) -> -2627.15 | G9: spotoify | H9: -20 | I9: yes
D10: Saving Total | E10: =SUM(E2:E9) -> 1511 | G10: rainy day | H10: -60 | I10: yes
D11: Emergency Fund | E11: 1006.73 | G11: netflix | H11: -4.99 | I11: yes
D12: Car Fund | E12: 1100.58 | G12: gym | H12: -27 | I12: yes
G13: council tax | H13: -225 | I13: yes
B14: 806.34 | G14: water | H14: -13 | I14: yes
B15: 891.38 | D15: 4674 | G15: window clean | H15: -10 | I15: no
B16: =B15+B14 -> 1697.72 | G16: water | H16: -29.2 | I16: yes
D17: check come in at 235 | G17: hp | H17: -4.49 | I17: yes
A18: Mortgage | D18: 100 to willow | G18: DISHWASHER | H18: -5 | I18: yes
A19: Main | B19: 154131.53 | D19: 165 TO FRAn | G19: fran money for card | H19: -800 | I19: yes | J19: f1
A20: Extra | B20: 81555.67 | D20: WV6KZMV | G20: tesco mobiles | H20: -27 | I20: yes | J20: f2
A21: Total Due | B21: =SUM(B19:B20) -> 235687.2 | D21: Silverboots69! | G21: credit card hsbc | H21: -5 | I21: yes | J21: f1
A22: H2B paybak | B22: =B23*0.2 -> 90000 | D22: JL092865B | G22: food petrol | H22: -850 | I22: yes | J22: f1
A23: Sold Price | B23: 450000 | G23: phone | H23: -11 | I23: yes
A24: Equity | B24: =B23-SUM(B21:B22) -> 124312.8 | D24: 264 on credit card to be made into cash | G24: greenbelt | H24: -7.6 | I24: yes
D25: 75 +190 | G25: holiday | H25: -250 | I25: yes
G26: car insurance lv | H26: -31 | I26: yes
G27: child benefit shit | H27: -150 | I27: yes | J27: f1
G28: zoom | H28: -18 | I28: yes
G29: gym | H29: -33 | I29: yes | J29: f2
G30: boiler | H30: -12 | I30: yes
G31: service | H31: -60 | I31: yes
G32: matt | H32: -290 | I32: yes
G33: dental | H33: -20 | I33: yes
G34: help to by | H34: -127 | I34: yes
G35: dishwasher | H35: -5 | I35: yes
G36: uniform | H36: -50 | I36: yes
G37: Savings | H37: -1100 | I37: yes

Sheet sept24
A1: Money | D1: Savings Account | G1: Name | H1: Value | I1: Paid? | J1: Who | K1: Category
A2: Paid | B2: 5205.3 | G2: Mortgage | H2: -1268.67 | I2: yes | K2: House
A3: Taken Already | B3: =SUMIF(I2:I47,"Yes*",H2:H47) -> -6163.26 | D3: Rainy Day 🌧️ | E3: 100 | G3: isa payment | I3: no | J3: s | K3: Savings
A4: Balance | B4: 518.36 | D4: Service Fund 🚗 | E4: 100 | G4: LifeInsurance/aviva | H4: -37 | I4: yes | K4: Insurance
A5: To Be Taken | B5: =SUMIF(I2:I47,"No",H2:H47) -> -466.87 | D5: Dental 🪥 | E5: 60 | G5: HouseInsurance - Tesco | H5: -39 | I5: yes | K5: Insurance
A6: Total | B6: =B5+B4 -> 51.49 | D6: Vet Fund 😺 | E6: 520 | G6: TvLicence | H6: -15 | I6: yes | K6: HouseBill
